Workbook
Name Slicer_TYPE: #N/A

Sheet New_Costing
G1: NOTE: THAT THE DIFFERENCE OF DECLARED VAT IMPORTATION IS 2-3% ONLY | AE1: Source | AF1: Date | AG1: Product Type | AH1: Supplier | AI1: Document Type | AJ1: Number | AK1: Particulars | AL1: Size | AM1: Code | AN1: Quantity | AP1: CPU | AQ1: Total Invoice | AR1: Less: VAT | AS1: Net of VAT | AT1: Computations
B2: OIL COSTING | G2: PROFITABILITY
I3: PALM OIL | P3: CANOLA OIL | S3: SOYA OIL | BH3: PAYMENT SUMMARY AND COST PER UNIT (Formulated Table)
BH4: Description | BI4: Amount | BJ4: CPU (KG) | BK4: CPU (LTR)
G5: DESCRIPTION | I5: 350ML | J5: 36 | K5: 500ML | L5: 24 | M5: 1LSWAK | N5: 12 | P5: 1LITER | Q5: 12 | S5: 1LITER | T5: 12 | BH5: As per Foreign Cost | BI5: =BF21+BF37 -> 2026160 | BJ5: =BI5/BD15 -> 94.24 | BK5: =BI5/BF16 -> 82.928546
B6: Description | C6: Date | D6: Price | E6: isUsed | G6: SALES | I6: 36 | J6: =I6/I6 -> 1 | K6: 50 | L6: =K6/K6 -> 1 | M6: 95 | N6: =M6/M6 -> 1 | P6: 105 | Q6: =P6/P6 -> 1 | S6: 115 | T6: =S6/S6 -> 1 | V6: MIXES | AA6: MOST RECENT PURCHASE PRICES | AT6: Price per KG ($) | AU6: Net Weight (L) | AV6: FX Rate | AW6: Total for COGS | AX6: COGS per KG | AY6: COGS per L | AZ6: COGS per bottle | BH6: As per Local Cost | BI6: =BK34+BJ20 -> 320231.29 | BJ6: =BI6/BD15 -> 14.894479 | BK6: =BI6/BF16 -> 13.106722
B7: ='Pricing Trends'!R13 -> RBD SOYA BEAN OIL | C7: ='Pricing Trends'!S13 -> 45314 | D7: ='Pricing Trends'!U13 -> 69.078872 | E7: FALSE | G7: RBD SOYA BEAN OIL | I7: =IFERROR(VLOOKUP($I$2&$G7,Validation!$E:$O,4,FALSE),0) -> 0 | J7: =I7/I$6 -> 0 | K7: =IFERROR(VLOOKUP($I$2&$G7,Validation!$E:$O,5,FALSE),0) -> 0 | L7: =K7/K$6 -> 0 | M7: =IFERROR(VLOOKUP($I$2&$G7,Validation!$E:$O,6,FALSE),0) -> 0 | N7: =M7/M$6 -> 0 | P7: =IFERROR(VLOOKUP($P$2&$G7,Validation!$E:$O,6,FALSE),0) -> 0 | Q7: =P7/P$6 -> 0 | S7: =Y15 -> 90.6633 | T7: =S7/S$6 -> 0.78837652 | V7: PALM | Y7: =SUM(Y8:Y13) -> 81.6612 | AA7: PALM (Local) | AB7: =AF33 -> 46158 | AC7: =AY33 -> 75.061598 | AE7: Wennie - Payables | AF7: 45901 | AG7: Corn | AH7: O.V. INTERNATIONAL IMPORT-EXPORT CO., LTD. | AK7: 24/15OZ CANNED WHOLE SWEET KERNEL CORN | AN7: 1050 | AO7: unit | AP7: 9.5 | AQ7: =AP7*AN7 -> 9975 | BH7: As per Gross of BOC | BI7: =BI5+BI6 -> 2346391.3 | BJ7: =BI7/BD15 -> 109.13448 | BK7: =BI7/BF16 -> 96.035268
B8: ='Pricing Trends'!R14 -> RBD SOYA BEAN OIL | C8: ='Pricing Trends'!S14 -> 45256 | D8: ='Pricing Trends'!U14 -> 68.75434 | E8: FALSE | G8: RBD PALM OLEIN (LOCAL) | I8: =IFERROR(VLOOKUP($I$2&$G8,Validation!$E:$O,4,FALSE),0) -> 0 | J8: =I8/I$6 -> 0 | K8: =IFERROR(VLOOKUP($I$2&$G8,Validation!$E:$O,5,FALSE),0) -> 0 | L8: =K8/K$6 -> 0 | M8: =IFERROR(VLOOKUP($I$2&$G8,Validation!$E:$O,6,FALSE),0) -> 0 | N8: =M8/M$6 -> 0 | P8: =IFERROR(VLOOKUP($P$2&$G8,Validation!$E:$O,6,FALSE),0) -> 0 | Q8: =P8/P$6 -> 0 | S8: =IFERROR(VLOOKUP($S$2&$G8,Validation!$E:$O,6,FALSE),0) -> 0 | T8: =S8/S$6 -> 0 | V8: PALM (Local) | W8: =$AC$7 -> 75.061598 | X8: 0 | Y8: =W8*X8 -> 0 | AA8: PALM (Foreign) | AB8: =AF12 -> 46093 | AC8: =AY12 -> 81.6612 | AE8: Wennie - Payables | AF8: 45901 | AG8: Corn | AH8: O.V. INTERNATIONAL IMPORT-EXPORT CO., LTD. | AK8: 24/15OZ CANNED CREAM STYLE CORN | AN8: 300 | AO8: unit | AP8: 9.5 | AQ8: =AP8*AN8 -> 2850 | BH8: As per Net of BOC | BI8: =BI7-BJ20 -> 2157411.1 | BJ8: =BI8/BD15 -> 100.3447 | BK8: =BI8/BF16 -> 88.300512
B9: ='Pricing Trends'!R15 -> RBD SOYA BEAN OIL | C9: ='Pricing Trends'!S15 -> 45132 | D9: ='Pricing Trends'!U15 -> 64.59293 | E9: FALSE | G9: RBD PALM OLEIN (FOREIGN) | I9: =M9*(350/1000) -> 28.58142 | J9: =I9/I$6 -> 0.79392833 | K9: =M9/2 -> 40.8306 | L9: =K9/K$6 -> 0.816612 | M9: =Y7 -> 81.6612 | N9: =M9/M$6 -> 0.85959158 | P9: =IFERROR(VLOOKUP($P$2&$G9,Validation!$E:$O,6,FALSE),0) -> 0 | Q9: =P9/P$6 -> 0 | S9: =IFERROR(VLOOKUP($S$2&$G9,Validation!$E:$O,6,FALSE),0) -> 0 | T9: =S9/S$6 -> 0 | V9: PALM (Foreign) | W9: =$AC$8 -> 81.6612 | X9: 1 | Y9: =W9*X9 -> 81.6612 | AA9: SOYA (Local) | AC9: 0 | AE9: Wennie - Payables | AF9: 45901 | AG9: Corn | AH9: O.V. INTERNATIONAL IMPORT-EXPORT CO., LTD. | AK9: 06/108OZ CANNED WHOLE KERNEL CORN | AN9: 200 | AO9: unit | AP9: 13.5 | AQ9: =AP9*AN9 -> 2700 | BH9: For COGS | BI9: =BF21+BJ20+BF37 -> 2215140.2 | BJ9: =BI9/BD15 -> 103.02978 | BK9: =BI9/BF16 -> 90.663303
B10: ='Pricing Trends'!R16 -> RBD SOYA BEAN OIL | C10: ='Pricing Trends'!S16 -> 44961 | D10: ='Pricing Trends'!U16 -> 81.901482 | E10: FALSE | G10: RBD CANOLA OIL | I10: =IFERROR(VLOOKUP($I$2&$G10,Validation!$E:$O,4,FALSE),0) -> 0 | J10: =I10/I$6 -> 0 | K10: =IFERROR(VLOOKUP($I$2&$G10,Validation!$E:$O,5,FALSE),0) -> 0 | L10: =K10/K$6 -> 0 | M10: =IFERROR(VLOOKUP($I$2&$G10,Validation!$E:$O,6,FALSE),0) -> 0 | N10: =M10/M$6 -> 0 | P10: =Y23 -> 84.3891 | Q10: =P10/P$6 -> 0.80370571 | S10: =IFERROR(VLOOKUP($S$2&$G10,Validation!$E:$O,6,FALSE),0) -> 0 | T10: =S10/S$6 -> 0 | V10: SOYA (Local) | W10: =$AC$9 -> 0 | X10: 0 | Y10: =W10*X10 -> 0 | AA10: SOYA (Foreign) | AB10: =AF13 -> 46093 | AC10: =AY13 -> 90.6633 | AE10: Wennie - Payables | AF10: 45960 | AG10: Coconut Milk | AH10: SUREE INTERFOODS CO. LTD | AK10: COCONUT MILK | AN10: 1800 | AO10: unit | AP10: 13.05 | AQ10: =AP10*AN10 -> 23490
B11: ='Pricing Trends'!R17 -> 0 | C11: ='Pricing Trends'!S17 -> 0 | D11: ='Pricing Trends'!U17 -> 0 | E11: FALSE | G11: RBD COCONUT OIL | I11: =IFERROR(VLOOKUP($I$2&$G11,Validation!$E:$O,4,FALSE),0) -> 0 | J11: =I11/I$6 -> 0 | K11: =IFERROR(VLOOKUP($I$2&$G11,Validation!$E:$O,5,FALSE),0) -> 0 | L11: =K11/K$6 -> 0 | M11: =IFERROR(VLOOKUP($I$2&$G11,Validation!$E:$O,6,FALSE),0) -> 0 | N11: =M11/M$6 -> 0 | P11: =IFERROR(VLOOKUP($P$2&$G11,Validation!$E:$O,6,FALSE),0) -> 0 | Q11: =P11/P$6 -> 0 | S11: =IFERROR(VLOOKUP($S$2&$G11,Validation!$E:$O,6,FALSE),0) -> 0 | T11: =S11/S$6 -> 0 | V11: SOYA (Foreign) | W11: =$AC$10 -> 90.6633 | X11: 0 | Y11: =W11*X11 -> 0 | AA11: CANOLA (LOCAL) | AC11: 0 | AE11: Wennie - Payables | AF11: 45964 | AG11: Canola Oil | AH11: MOI INTERNATIONAL (SIGNAPORE) PTE LTD | AK11: RBD CANOLA OIL | AN11: 21.5 | AO11: MT | AP11: 1405 | AQ11: =AP11*AN11 -> 30207.5 | AR11: =AN11*1000 -> 21500 | AS11: =AQ11/AR11 -> 1.405 | AT11: 1.405 | AU11: 24433 | AV11: 62 | AW11: 2061845.2 | AX11: 95.8998 | AY11: 84.3891 | BB11: DETAILS OF PAYMENT
B12: ='Pricing Trends'!R18 -> RBD COCONUT OIL | C12: ='Pricing Trends'!S18 -> 45468 | D12: ='Pricing Trends'!U18 -> 64.678486 | E12: FALSE | G12: LABEL | I12: =IFERROR(VLOOKUP("350ML LABEL PALM",'Pricing Trends'!$K:$N,4,FALSE),0) -> 0.3 | J12: =I12/I$6 -> 0.0083333333 | K12: =IFERROR(VLOOKUP("500ML LABEL PALM",'Pricing Trends'!$K:$N,4,FALSE),0) -> 0.45 | L12: =K12/K$6 -> 0.009 | M12: =IFERROR(VLOOKUP("1LITER LABEL PALM",'Pricing Trends'!$K:$N,4,FALSE),0) -> 0.55 | N12: =M12/M$6 -> 0.0057894737 | P12: =IFERROR(VLOOKUP("1LITER LABEL CANOLEIN",'Pricing Trends'!$K:$N,4,FALSE),0) -> 0.72 | Q12: =P12/P$6 -> 0.0068571429 | S12: =IFERROR(VLOOKUP("1LITER LABEL SOYA",'Pricing Trends'!$K:$N,4,FALSE),0) -> 0.72 | T12: =S12/S$6 -> 0.0062608696 | V12: CANOLA (LOCAL) | W12: =$AC$11 -> 0 | X12: 0 | Y12: =W12*X12 -> 0 | AA12: CANOLA (Foreign) | AB12: =AF11 -> 45964 | AC12: =AY11 -> 84.3891 | AE12: Wennie - Payables | AF12: 46093 | AG12: Palm Oil | AH12: MOI INTERNATIONAL (SIGNAPORE) PTE LTD | AK12: RBD PALM OLEIN - IV 60 MIN | AN12: 21.5 | AO12: MT | AP12: 1355 | AQ12: =AP12*AN12 -> 29132.5 | AR12: =AN12*1000 -> 21500 | AS12: =AQ12/AR12 -> 1.355 | AT12: 1.355 | AU12: 24433 | AV12: 62 | AW12: 1995195.2 | AX12: 92.7998 | AY12: 81.6612
B13: ='Pricing Trends'!R19 -> RBD COCONUT OIL | C13: ='Pricing Trends'!S19 -> 45222 | D13: ='Pricing Trends'!U19 -> 51.4783 | E13: FALSE | G13: BOTTLE / POUCH | I13: =AC18 -> 3.95 | J13: =I13/I$6 -> 0.10972222 | K13: =IFERROR(VLOOKUP("500ML BOTTLE PALM [SWAK]",'Pricing Trends'!$A:$D,4,FALSE),0) -> 3.65 | L13: =K13/K$6 -> 0.073 | M13: =AC20 -> 7.9 | N13: =M13/M$6 -> 0.083157895 | P13: =AC20 -> 7.9 | Q13: =P13/P$6 -> 0.075238095 | S13: =AC20 -> 7.9 | T13: =S13/S$6 -> 0.068695652 | V13: CANOLA (Foreign) | W13: =$AC$12 -> 84.3891 | X13: 0 | Y13: =W13*X13 -> 0 | AE13: Wennie - Payables | AF13: 46093 | AG13: Soybean Oil | AH13: MOI INTERNATIONAL (SIGNAPORE) PTE LTD | AK13: RBD SOYBEAN OIL | AN13: 21.5 | AO13: MT | AP13: 1520 | AQ13: =AP13*AN13 -> 32680 | AR13: =AN13*1000 -> 21500 | AS13: =AQ13/AR13 -> 1.52 | AT13: 1.52 | AU13: 24433 | AV13: 62 | AW13: 2215140.2 | AX13: 103.0298 | AY13: 90.6633
B14: ='Pricing Trends'!R20 -> RBD COCONUT OIL | C14: ='Pricing Trends'!S20 -> 45133 | D14: ='Pricing Trends'!U20 -> 54.559 | E14: FALSE | G14: BOX | I14: =AC14 -> 0.72222222 | J14: =I14/I$6 -> 0.020061728 | K14: =AC15 -> 0.87083333 | L14: =K14/K$6 -> 0.017416667 | M14: =AC16 -> 2.15 | N14: =M14/M$6 -> 0.022631579 | P14: =AC16 -> 2.15 | Q14: =P14/P$6 -> 0.02047619 | S14: =AC16 -> 2.15 | T14: =S14/S$6 -> 0.018695652 | AA14: Box 350mL | AB14: =AF36 -> 46180 | AC14: =AZ36 -> 0.72222222 | AE14: Wennie - Payables | AF14: 46119 | AG14: Corn Starch | AH14: QINGDAO BAONA BIOLOGICAL TECHNOLOGY CP., LTD | AK14: CORN STARCH | AN14: 28.4 | AO14: MT | AP14: 450 | AQ14: =AP14*AN14 -> 12780 | BB14: ORDER DETAILS (FOREIGN) | BH14: COMPUTATION OF TAXES AND DUTIES
B15: ='Pricing Trends'!R21 -> RBD COCONUT OIL | C15: ='Pricing Trends'!S21 -> 44965 | D15: ='Pricing Trends'!U21 -> 52.7983 | E15: FALSE | G15: PACKAGING TAPE CLEAR | I15: =((IFERROR(VLOOKUP($G$15,'Pricing Trends'!$W:$Z,4,FALSE),0)/10000)*200)/J5 -> 0.013888889 | J15: =I15/I$6 -> 0.00038580247 | K15: =((IFERROR(VLOOKUP($G$15,'Pricing Trends'!$W:$Z,4,FALSE),0)/10000)*200)/L5 -> 0.020833333 | L15: =K15/K$6 -> 0.00041666667 | M15: =((IFERROR(VLOOKUP($G$15,'Pricing Trends'!$W:$Z,4,FALSE),0)/10000)*200)/N5 -> 0.041666667 | N15: =M15/M$6 -> 0.00043859649 | P15: =((IFERROR(VLOOKUP($G$15,'Pricing Trends'!$W:$Z,4,FALSE),0)/10000)*200)/Q5 -> 0.041666667 | Q15: =P15/P$6 -> 0.0003968254 | S15: =((IFERROR(VLOOKUP($G$15,'Pricing Trends'!$W:$Z,4,FALSE),0)/10000)*200)/T5 -> 0.041666667 | T15: =S15/S$6 -> 0.00036231884 | V15: SOYA | Y15: =SUM(Y16:Y21) -> 90.6633 | AA15: Box 500mL | AB15: =AF34 -> 46178 | AC15: =AZ34 -> 0.87083333 | AE15: Wennie - Receipts | AF15: 46140 | AG15: Bottle 1L | AH15: RMC RICOR MILLS CORP. | AI15: CLIENT ACKNOWLEDGEMENT RECEIPT | AJ15: 0010628 | AK15: 1LTR36G1810 Clear-Swak | AL15: 91 Bags x 110 pcs | AM15: FG082 | AN15: 10010 | AO15: pcs | AP15: 7.2 | AQ15: =AN15*AP15 -> 72072 | BB15: ITEM NET WEIGHT (KG) | BD15: =21.5*1000 -> 21500 | BE15: PRICE PER KG | BF15: =BD16/BD15 -> 1.52 | BH15: VAT PH (12%) | BJ15: Formulated | BK15: =BF34*0.12 -> 253684.78
B16: ='Pricing Trends'!R22 -> 0 | C16: ='Pricing Trends'!S22 -> 0 | D16: ='Pricing Trends'!U22 -> 0 | E16: FALSE | G16: DOUBLE SIDED TAPE 3/4"X30M | I16: =((45/3000)*7) -> 0.105 | J16: =I16/I$6 -> 0.0029166667 | K16: =((45/3000)*7) -> 0.105 | L16: =K16/K$6 -> 0.0021 | M16: =((45/3000)*12) -> 0.18 | N16: =M16/M$6 -> 0.0018947368 | Q16: =P16/P$6 -> 0 | T16: =S16/S$6 -> 0 | V16: PALM (Local) | W16: =$AC$7 -> 75.061598 | X16: 0 | Y16: =W16*X16 -> 0 | AA16: Box 1L | AB16: =AF35 -> 46179 | AC16: =AZ35 -> 2.15 | AE16: Wennie - Receipts | AF16: 46140 | AG16: Bottle 350mL | AH16: RMC RICOR MILLS CORP. | AI16: CLIENT ACKNOWLEDGEMENT RECEIPT | AJ16: 0010628 | AK16: 350ML17G1810 Clear-Swak | AL16: 72 Bags x 210 pcs | AM16: FG179A | AN16: 15120 | AO16: pcs | AP16: 3.1 | AQ16: =AN16*AP16 -> 46872 | BB16: DOLLAR PAYMENT | BD16: =AQ13 -> 32680 | BE16: NET WEIGHT (LTR) | BF16: =BD15*1.1364 -> 24432.6 | BH16: Minimum VAT | BJ16: 186569.21 | BK16: =BJ16-BK15 -> -67115.572
B17: ='Pricing Trends'!R23 -> RBD PALM OLEIN (FOREIGN) | C17: ='Pricing Trends'!S23 -> 45547 | D17: ='Pricing Trends'!U23 -> 60.65316 | E17: FALSE | G17: COST OF GOODS SOLD | I17: =SUM(I7:I16) -> 33.672531 | J17: =I17/I6 -> 0.93534809 | K17: =SUM(K7:K16) -> 45.927267 | L17: =K17/K6 -> 0.91854533 | M17: =SUM(M7:M16) -> 92.482867 | N17: =M17/M6 -> 0.97350386 | P17: =SUM(P7:P16) -> 95.200767 | Q17: =P17/P6 -> 0.90667397 | S17: =SUM(S7:S16) -> 101.47497 | T17: =S17/S6 -> 0.88239101 | V17: PALM (Foreign) | W17: =$AC$8 -> 81.6612 | X17: 0 | Y17: =W17*X17 -> 0 | AE17: Wennie - Receipts | AF17: 46140 | AG17: Bottle Caps | AI17: CLIENT ACKNOWLEDGEMENT RECEIPT | AJ17: 0010628 | AK17: 1810Caps-Yellow | AL17: 6 Bags x 4000 + 1130 pcs | AM17: CP105 | AN17: 25130 | AO17: pcs | AP17: 0.7 | AQ17: =AP17*AN17 -> 17591 | AZ17: =AP17 -> 0.7 | BB17: FOREIGN EXCHANGE RATE | BF17: 62 | BH17: Import Processing Fee (IPF) | BJ17: Formulated | BK17: 2000
B18: ='Pricing Trends'!R24 -> RBD PALM OLEIN (FOREIGN) | C18: ='Pricing Trends'!S24 -> 45517 | D18: ='Pricing Trends'!U24 -> 60.97 | E18: FALSE | G18: GROSS PROFIT | I18: =I6-I17 -> 2.3274689 | J18: =I18/I6 -> 0.064651914 | K18: =K6-K17 -> 4.0727333 | L18: =K18/K6 -> 0.081454667 | M18: =M6-M17 -> 2.5171333 | N18: =M18/M6 -> 0.02649614 | P18: =P6-P17 -> 9.7992333 | Q18: =P18/P6 -> 0.093326032 | S18: =S6-S17 -> 13.525033 | T18: =S18/S6 -> 0.11760899 | V18: SOYA (Local) | W18: =$AC$9 -> 0 | X18: 0 | Y18: =W18*X18 -> 0 | AA18: Bottle 350mL | AB18: =AF36 -> 46180 | AC18: =AZ26 -> 3.95 | AE18: Angie | AF18: 46140 | AG18: Bottle 1L | AH18: MCBRIDE | AK18: 1 LTER BOTTLE PALM (SWAK) | AN18: 10010 | AO18: pcs | AP18: 7.9 | AQ18: =AN18*AP18 -> 79079 | BH18: Customs Documentary Stamp (CDS) | BJ18: Fixed | BK18: 130
B19: ='Pricing Trends'!R25 -> RBD PALM OLEIN (FOREIGN) | C19: ='Pricing Trends'!S25 -> 45494 | D19: ='Pricing Trends'!U25 -> 60.49687 | E19: FALSE | G19: EXPENSES | I19: =SUM(I20:I35) -> 1.1308955 | J19: =I19/I6 -> 0.031413763 | K19: =SUM(K20:K35) -> 4.4376435 | L19: =K19/K6 -> 0.08875287 | M19: =SUM(M20:M35) -> 2.7025585 | N19: =M19/M6 -> 0.028447984 | P19: =SUM(P20:P35) -> 14.019373 | Q19: =P19/P6 -> 0.13351784 | S19: =SUM(S20:S35) -> 15.432276 | T19: =S19/S6 -> 0.1341937 | V19: SOYA (Foreign) | W19: =$AC$10 -> 90.6633 | X19: 1 | Y19: =W19*X19 -> 90.6633 | AA19: Bottle 500mL | AC19: 0 | AE19: Angie | AF19: 46140 | AG19: Bottle 350mL | AH19: MCBRIDE | AK19: 350ML BOTTLE PALM (SWAK) | AN19: 15120 | AO19: pcs | AP19: 3.8 | AQ19: =AN19*AP19 -> 57456 | BB19: BOC COMPUTATION | BH19: Container Security Fees (CSF) | BJ19: Fixed | BK19: 281
B20: ='Pricing Trends'!R26 -> RBD PALM OLEIN (FOREIGN) | C20: ='Pricing Trends'!S26 -> 45314 | D20: ='Pricing Trends'!U26 -> 57.51356 | E20: FALSE | G20: Production Expenses - Labelling | I20: 0.2 | J20: =I20/I$6 -> 0.0055555556 | K20: 0.2 | L20: =K20/K$6 -> 0.004 | M20: 0.2 | N20: =M20/M$6 -> 0.0021052632 | Q20: =P20/P$6 -> 0 | V20: CANOLA (LOCAL) | W20: =$AC$11 -> 0 | X20: 0 | Y20: =W20*X20 -> 0 | AA20: Bottle 1L | AB20: =AF32 -> 46151 | AC20: =AZ32 -> 7.9 | AE20: Wennie - Receipts | AF20: 46148 | AG20: Box 350mL | AH20: SUPERIOR PACKAGING CORPORATION | AI20: SALES INVOICE | AJ20: 552335 | AK20: Corrugated Carton RSC IN-GLUED Joint, B Flute, 175# lbs. 2 color | AL20: 385 X 385 X 190 | AM20: 350ML BOX PALM | AN20: 6225 | AO20: pcs | AP20: 26 | AQ20: =AN20*AP20 -> 161850 | AR20: =AQ20/1.12*0.12 -> 17341.071 | AS20: =AQ20-AR20 -> 144508.93 | AZ20: =AP20/36 -> 0.72222222 | BB20: MEN2 PAYMENT IN PESO VALUE | BH20: TOTAL DUTIES AND TAXES | BJ20: =SUM(BK15:BK19) -> 188980.21
B21: ='Pricing Trends'!R27 -> RBD PALM OLEIN (FOREIGN) | C21: ='Pricing Trends'!S27 -> 45248 | D21: ='Pricing Trends'!U27 -> 61.45051 | E21: FALSE | G21: Production Expenses - Packaging | I21: =0.4*0.35 -> 0.14 | J21: =I21/I$6 -> 0.0038888889 | K21: =0.4*0.5 -> 0.2 | L21: =K21/K$6 -> 0.004 | M21: 0.4 | N21: =M21/M$6 -> 0.0042105263 | P21: 0.4 | Q21: =P21/P$6 -> 0.0038095238 | S21: 0.4 | T21: =S21/S$6 -> 0.0034782609 | V21: CANOLA (Foreign) | W21: =$AC$12 -> 84.3891 | X21: 0 | Y21: =W21*X21 -> 0 | AA21: Bottle 350mL - Price increase | AC21: =AZ38 -> 4.1 | AE21: Wennie - Receipts | AF21: 46148 | AG21: Box 500mL | AH21: SUPERIOR PACKAGING CORPORATION | AI21: SALES INVOICE | AJ21: 552333 | AK21: Corrugated Carton RSC IN-GLUED Joint, B Flute, 175# lbs. 2 color | AL21: 2416 X 285 X 230 | AM21: 500ML BOX PALM | AN21: 2000 | AO21: pcs | AP21: 20.9 | AQ21: =AN21*AP21 -> 41800 | AR21: =AQ21/1.12*0.12 -> 4478.5714 | AS21: =AQ21-AR21 -> 37321.429 | AZ21: =AP21/24 -> 0.87083333 | BB21: Item Custom Value (Oil) | BE21: Formulated | BF21: =BD16*BF17 -> 2026160
B22: ='Pricing Trends'!R28 -> RBD PALM OLEIN (FOREIGN) | C22: ='Pricing Trends'!S28 -> 45244 | D22: ='Pricing Trends'!U28 -> 63.35264 | E22: FALSE | G22: Distributors Discount | AA22: Bottle 500mL - Price Increase | AC22: 0 | AE22: Wennie - Receipts | AF22: 46149 | AG22: Box 1L | AH22: SUPERIOR PACKAGING CORPORATION | AI22: SALES INVOICE | AJ22: 552334 | AK22: Corrugated Carton RSC IN-GLUED Joint, B Flute, 200 lbs. 2 color | AL22: 344 X 258 X 281 | AM22: 1 LITER BOX PALM - SWAK | AN22: 7425 | AO22: pcs | AP22: 25.8 | AQ22: =AN22*AP22 -> 191565 | AR22: =AQ22/1.12*0.12 -> 20524.821 | AS22: =AQ22-AR22 -> 171040.18 | AZ22: =AP22/12 -> 2.15 | BB22: SUPPLIER DUTIES | BH22: COMPUTATION OF SHIPPING FEE
B23: ='Pricing Trends'!R29 -> RBD PALM OLEIN (FOREIGN) | C23: ='Pricing Trends'!S29 -> 45234 | D23: ='Pricing Trends'!U29 -> 56.63575 | E23: FALSE | G23: Sales Expenses - Internal | V23: CANOLA | Y23: =SUM(Y24:Y29) -> 84.3891 | AA23: Bottle 1L - Price Increase | AC23: =AZ37 -> 8.6 | AE23: Wennie - Receipts | AF23: 46150 | AG23: Bottle 350mL | AI23: CLIENT ACKNOWLEDGEMENT RECEIPT | AJ23: 0010679 | AK23: 350ml17g1810Clear-Swak | AL23: 209 Bags x 230 pcs | AM23: FG179S | AN23: 43890 | AO23: pcs | AP23: 3.25 | AQ23: =AP23*AN23 -> 142642.5 | AZ23: =AP23 -> 3.25 | BB23: InsuranceInFreight | BD23: Formulated | BE23: 25029 | BF23: =SUM(BE23:BE24) -> 73205 | BH23: Shippine Lines THC Fee | BJ23: Variable | BK23: 42510
B24: ='Pricing Trends'!R30 -> 0 | C24: ='Pricing Trends'!S30 -> 0 | D24: ='Pricing Trends'!U30 -> 0 | E24: FALSE | G24: Sales Expenses - External | J24: =I24/I$6 -> 0 | K24: 1 | N24: =M24/M$6 -> 0 | P24: 1 | Q24: =P24/P$6 -> 0.0095238095 | S24: 1 | T24: =S24/S$6 -> 0.0086956522 | V24: PALM (Local) | W24: =$AC$7 -> 75.061598 | X24: 0 | Y24: =W24*X24 -> 0 | AE24: Wennie - Receipts | AF24: 46150 | AG24: Bottle Caps | AI24: CLIENT ACKNOWLEDGEMENT RECEIPT | AJ24: 0010679 | AK24: 1810Caps-Yellow | AL24: 10 Bags x 4000 + 3890 pcs | AM24: CP105 | AN24: 43890 | AO24: pcs | AP24: 0.7 | AQ24: =AP24*AN24 -> 30723 | AZ24: =AP24 -> 0.7 | BB24: OTHinEV | BD24: Formulated | BE24: 48176 | BH24: Storage Fee | BJ24: Variable | BK24: 2846.23
B25: ='Pricing Trends'!R31 -> RBD CANOLA OIL | C25: ='Pricing Trends'!S31 -> 45269 | D25: ='Pricing Trends'!U31 -> 73.180847 | E25: FALSE | G25: Marketing Expenses - Trade Investment | V25: PALM (Foreign) | W25: =$AC$8 -> 81.6612 | X25: 0 | Y25: =W25*X25 -> 0 | AA25: PALM Pickup Logistics | AB25: 5/23/26 | AC25: =AZ40 -> 0.20255846 | AE25: Wennie - Receipts | AF25: 46150 | AG25: Pancit Canton | AI25: Finished Good Form | AK25: Mama Pina's Pancit Canton 300g x 18 | AN25: 120 | AO25: box | AP25: 820.8 | AQ25: =AP25*AN25 -> 98496 | BB25: CUSTOMS DUTIABLE VALUE (CUD) | BF25: =SUM(BF21:BF23) -> 2099365 | BH25: Custom SOP | BJ25: Variable | BK25: 18000
B26: ='Pricing Trends'!R32 -> RBD CANOLA OIL | C26: ='Pricing Trends'!S32 -> 45118 | D26: ='Pricing Trends'!U32 -> 80.463781 | E26: FALSE | G26: Marketing Expenses - Brand Building | V26: SOYA (Local) | W26: =$AC$9 -> 0 | X26: 0 | Y26: =W26*X26 -> 0 | AE26: Angie | AF26: 46150 | AG26: Bottle 350mL | AH26: MCBRIDE | AK26: 350ML BOTTLE PALM (SWAK) | AN26: 43890 | AO26: pcs | AP26: 3.95 | AQ26: =AN26*AP26 -> 173365.5 | AZ26: =AP26 -> 3.95 | BB26: CUSTOM DUTIES | BH26: Processing Fee | BJ26: Fixed | BK26: 6000
B27: ='Pricing Trends'!R33 -> 0 | C27: ='Pricing Trends'!S33 -> 0 | D27: ='Pricing Trends'!U33 -> 0 | E27: FALSE | G27: General and Administrative Expenses | I27: =I6*0.01 -> 0.36 | J27: =I27/I$6 -> 0.01 | K27: =K6*0.01 -> 0.5 | L27: =K27/K$6 -> 0.01 | M27: =M6*0.01 -> 0.95 | N27: =M27/M$6 -> 0.01 | P27: =P6*0.01 -> 1.05 | Q27: =P27/P$6 -> 0.01 | S27: =S6*0.01 -> 1.15 | T27: =S27/S$6 -> 0.01 | V27: SOYA (Foreign) | W27: =$AC$10 -> 90.6633 | X27: 0 | Y27: =W27*X27 -> 0 | AE27: Wennie - Receipts | AF27: 46151 | AG27: Bottle 1L | AI27: CLIENT ACKNOWLEDGEMENT RECEIPT | AJ27: 0010686 | AK27: 1LTR36G1810Clear-Swak | AL27: 158 Bags x 110 Pcs | AM27: FG082 | AN27: 17380 | AO27: pcs | AP27: 7.2 | AQ27: =AP27*AN27 -> 125136 | AZ27: =AP27 -> 7.2 | BB27: Bank Charges | BD27: Variable | BE27: 0 | BF27: =SUM(BE27:BE33) -> 14674.85 | BH27: Documentation | BJ27: Fixed | BK27: 2000
B28: ='Pricing Trends'!R34 -> 0 | C28: ='Pricing Trends'!S34 -> 0 | D28: ='Pricing Trends'!U34 -> 0 | E28: FALSE | G28: Utilities Expenses | I28: =I6*0.01 -> 0.36 | J28: =I28/I$6 -> 0.01 | K28: =K6*0.01 -> 0.5 | L28: =K28/K$6 -> 0.01 | M28: =M6*0.01 -> 0.95 | N28: =M28/M$6 -> 0.01 | P28: =P6*0.01 -> 1.05 | Q28: =P28/P$6 -> 0.01 | S28: =S6*0.01 -> 1.15 | T28: =S28/S$6 -> 0.01 | V28: CANOLA (LOCAL) | W28: =$AC$11 -> 0 | X28: 0 | Y28: =W28*X28 -> 0 | AA28: OLD DATA | AE28: Wennie - Receipts | AF28: 46151 | AG28: Bottle Caps | AI28: CLIENT ACKNOWLEDGEMENT RECEIPT | AJ28: 0010686 | AK28: 1810Caps-Yellow | AL28: 4 Bags x 4000 + 1380 pcs | AM28: CP105 | AN28: 17380 | AO28: pcs | AP28: 0.7 | AQ28: =AP28*AN28 -> 12166 | AZ28: =AP28 -> 0.7 | BB28: Customs Duty | BD28: Variable | BE28: 0 | BH28: Local Trucking | BJ28: Fixed | BK28: 42000
B29: ='Pricing Trends'!R35 -> 0 | C29: ='Pricing Trends'!S35 -> 0 | D29: ='Pricing Trends'!U35 -> 0 | E29: FALSE | G29: Logistics Expenses - Delivery | J29: =I29/I$6 -> 0 | L29: =K29/K$6 -> 0 | N29: =M29/M$6 -> 0 | P29: =P6*0.03 -> 3.15 | Q29: =P29/P$6 -> 0.03 | S29: =S6*0.03 -> 3.45 | T29: =S29/S$6 -> 0.03 | V29: CANOLA (Foreign) | W29: =$AC$12 -> 84.3891 | X29: 1 | Y29: =W29*X29 -> 84.3891 | AE29: Wennie - Receipts | AF29: 46151 | AG29: Palm Oil | AI29: Finished Good Form | AK29: Mama Pina's Palm Oil 350ml x 36 BAS | AN29: 182 | AO29: box | AP29: 953.05 | AQ29: =AP29*AN29 -> 173455.1 | BB29: Brokerage Fee | BD29: Formulated | BE29: 6975.74 | BH29: Customs Handling Charges | BJ29: Fixed | BK29: 1500
B30: ='Pricing Trends'!R36 -> 0 | C30: ='Pricing Trends'!S36 -> 0 | D30: ='Pricing Trends'!U36 -> 0 | E30: FALSE | G30: Logistics Expenses - Pick Up | H30: l | I30: =M30*(35/100) -> 0.070895462 | J30: =I30/I$6 -> 0.0019693184 | K30: =M30*0.5 -> 0.10127923 | L30: =K30/K$6 -> 0.0020255846 | M30: =AZ40 -> 0.20255846 | N30: =M30/M$6 -> 0.0021321944 | P30: =((IFERROR(VLOOKUP(P2&$G$11,Validation!$E:$F,2,FALSE),0)*'Pick Up Cost'!$C$16)+(IFERROR(VLOOKUP(P2&$G$8,Validation!$E:$F,2,FALSE),0)*'Pick Up Cost'!$C$16)) -> 0 | Q30: =P30/P$6 -> 0 | S30: =((IFERROR(VLOOKUP(S2&$G$11,Validation!$E:$F,2,FALSE),0)*'Pick Up Cost'!$C$16)+(IFERROR(VLOOKUP(S2&$G$8,Validation!$E:$F,2,FALSE),0)*'Pick Up Cost'!$C$16)) -> 0 | T30: =S30/S$6 -> 0 | AE30: Wennie - Receipts | AF30: 46151 | AG30: Palm Oil | AI30: Finished Good Form | AK30: Mama Pina's Palm Oil 1L x 12 MZL BAS | AN30: 191 | AO30: box | AP30: 1486.2 | AQ30: =AP30*AN30 -> 283864.2 | BB30: Wharfage Due | BD30: Variable | BE30: 581.67 | BH30: Customs OT | BJ30: Fixed | BK30: 2000
B31: ='Pricing Trends'!R37 -> 0 | C31: ='Pricing Trends'!S37 -> 0 | D31: ='Pricing Trends'!U37 -> 0 | E31: FALSE | G31: Logistics Expenses - THC and Customs | I31: =M31*0.35 -> 0 | J31: =I31/I$6 -> 0 | K31: =M31*0.5 -> 0 | L31: =K31/K$6 -> 0 | N31: =M31/M$6 -> 0 | P31: =((IFERROR(VLOOKUP(P2&$G$7,Validation!$E:$F,2,FALSE),0)*'Shipping Cost'!$E$4)+(IFERROR(VLOOKUP(P2&$G$9,Validation!$E:$F,2,FALSE),0)*'Shipping Cost'!$C$4)+(IFERROR(VLOOKUP(P2&$G$10,Validation!$E:$F,2,FALSE),0)*'Shipping Cost'!$D$4)) -> 0 | Q31: =P31/P$6 -> 0 | S31: =((IFERROR(VLOOKUP(S2&$G$7,Validation!$E:$F,2,FALSE),0)*'Shipping Cost'!$E$4)+(IFERROR(VLOOKUP(S2&$G$9,Validation!$E:$F,2,FALSE),0)*'Shipping Cost'!$C$4)+(IFERROR(VLOOKUP(S2&$G$10,Validation!$E:$F,2,FALSE),0)*'Shipping Cost'!$D$4)) -> 0 | T31: =S31/S$6 -> 0 | AE31: Wennie - Receipts | AF31: 46151 | AG31: Palm Oil | AI31: Finished Good Form | AK31: Mama Pina's Palm Oil 1L x 12 BAS | AN31: 340 | AO31: box | AP31: 854.65 | AQ31: =AP31*AN31 -> 290581 | BB31: Arrastre Charge | BD31: Variable | BE31: 5837.44 | BH31: Xray Charges | BJ31: Fixed | BK31: 1000
B32: ='Pricing Trends'!R38 -> RBD COCONUT OIL | C32: ='Pricing Trends'!S38 -> 45468 | D32: ='Pricing Trends'!U38 -> 85.357269 | E32: FALSE | G32: Dollar Fluctuation Allowance Pricing | J32: =I32/I$6 -> 0 | K32: =K6*0.01 -> 0.5 | L32: =K32/K$6 -> 0.01 | N32: =M32/M$6 -> 0 | P32: =P10*0.05 -> 4.219455 | Q32: =P32/P$6 -> 0.040185286 | S32: =S7*0.05 -> 4.533165 | T32: =S32/S$6 -> 0.039418826 | AE32: Angie | AF32: 46151 | AG32: Bottle 1L | AH32: MCBRIDE | AK32: 1 LTER BOTTLE PALM (SWAK) | AL32: Pickup Php 7k | AN32: 17380 | AO32: pcs | AP32: 7.9 | AQ32: =AN32*AP32 -> 137302 | AZ32: =AP32 -> 7.9 | BB32: Documentary Stamp | BD32: Fixed | BE32: 280 | BH32: Custom Duties | BJ32: Formulated | BK32: =SUM(BE29:BE31) -> 13394.85
B33: ='Pricing Trends'!R39 -> 0 | C33: ='Pricing Trends'!S39 -> 0 | D33: ='Pricing Trends'!U39 -> 0 | E33: FALSE | G33: Cost of Money | J33: =I33/I$6 -> 0 | K33: =K6*0.01 -> 0.5 | L33: =K33/K$6 -> 0.01 | N33: =M33/M$6 -> 0 | P33: =P6*0.01 -> 1.05 | Q33: =P33/P$6 -> 0.01 | S33: =S6*0.01 -> 1.15 | T33: =S33/S$6 -> 0.01 | AE33: Wennie - Receipts | AF33: 46158 | AG33: Palm Oil | AH33: RMC RICOR MILLS CORP. | AI33: DELIVERY RECEIPT | AJ33: 2601-214 | AK33: Pick Up RBD Palm Oil | AN33: 30410 | AO33: KG | AP33: 85.3 | AQ33: =AN33*AP33 -> 2593973 | AR33: =AQ33/1.12*0.12 -> 277925.68 | AS33: =AQ33-AR33 -> 2316047.3 | AU33: =AN33*1.1364 -> 34557.924 | AW33: =AQ33 -> 2593973 | AX33: =AQ33/AN33 -> 85.3 | AY33: =AQ33/AU33 -> 75.061598 | BB33: Others | BD33: Fixed | BE33: 1000 | BH33: Miscellaneous | BJ33: Variable | BK33: 0
B34: ='Pricing Trends'!R40 -> RBD CANOLA OIL | C34: ='Pricing Trends'!S40 -> 0 | D34: ='Pricing Trends'!U40 -> 83.220041 | E34: TRUE | G34: Value Added Tax | J34: =I34/I$6 -> 0 | K34: =((K6/1.12)*0.12)-((K17/1.12)*0.12) -> 0.43636429 | L34: =K34/K$6 -> 0.0087272857 | N34: =M34/M$6 -> 0 | P34: =((P6/1.12)*0.12)-((P17/1.12)*0.12) -> 1.0499179 | Q34: =P34/P$6 -> 0.0099992177 | S34: =((S6/1.12)*0.12)-((S17/1.12)*0.12) -> 1.4491107 | T34: =S34/S$6 -> 0.012600963 | AE34: Angie | AF34: 46178 | AG34: Box 500mL | AH34: MCBRIDE | AK34: 500ML BOX PALM | AN34: 2000 | AO34: pcs | AP34: 20.9 | AQ34: =AN34*AP34 -> 41800 | AZ34: =AP34/24 -> 0.87083333 | BB34: TOTAL LANDED COST (TLC) | BE34: =SUM(BE25:BE33) -> 14674.85 | BF34: =SUM(BF25:BF32) -> 2114039.9 | BH34: TOTAL SHIPPING FEES | BJ34: =BK34/BF16 -> 5.3719653 | BK34: =SUM(BK23:BK33) -> 131251.08
B35: ='Pricing Trends'!R41 -> RBD SOYA BEAN OIL | C35: ='Pricing Trends'!S41 -> 0 | D35: ='Pricing Trends'!U41 -> 81.666042 | E35: TRUE | G35: Income Tax | J35: =I35/I$6 -> 0 | K35: =K6*0.01 -> 0.5 | L35: =K35/K$6 -> 0.01 | N35: =M35/M$6 -> 0 | P35: =P6*0.01 -> 1.05 | Q35: =P35/P$6 -> 0.01 | S35: =S6*0.01 -> 1.15 | T35: =S35/S$6 -> 0.01 | AE35: Angie | AF35: 46179 | AG35: Box 1L | AH35: MCBRIDE | AK35: 1 LITER BOX PALM SWAK | AN35: 7425 | AO35: pcs | AP35: 25.8 | AQ35: =AN35*AP35 -> 191565 | AZ35: =AP35/12 -> 2.15
B36: ='Pricing Trends'!R42 -> 0 | C36: ='Pricing Trends'!S42 -> 0 | D36: ='Pricing Trends'!U42 -> 0 | E36: FALSE | G36: NET PROFIT | I36: =I18-I19 -> 1.1965734 | J36: =I36/I6 -> 0.033238151 | K36: =K18-K19 -> -0.36491018 | L36: =K36/K6 -> -0.0072982037 | M36: =M18-M19 -> -0.18542513 | N36: =M36/M6 -> -0.0019518435 | P36: =P18-P19 -> -4.2201395 | Q36: =P36/P6 -> -0.040191805 | S36: =S18-S19 -> -1.9072424 | T36: =S36/S6 -> -0.016584716 | AE36: Angie | AF36: 46180 | AG36: Box 350mL | AH36: MCBRIDE | AK36: 350 LM BOX PALM | AN36: 6225 | AO36: pcs | AP36: 26 | AQ36: =AN36*AP36 -> 161850 | AZ36: =AP36/36 -> 0.72222222 | BB36: DISCREPANCY
B37: ='Pricing Trends'!R43 -> RBD PALM OLEIN (FOREIGN) | C37: ='Pricing Trends'!S43 -> 0 | D37: ='Pricing Trends'!U43 -> 64.843399 | E37: FALSE | AE37: Angie | AG37: Bottle 1L | AH37: Price Increase Chat | AK37: 1L Bottle - Price Increase Chat | AP37: 8.6 | AZ37: =AP37 -> 8.6 | BB37: DOLLAR PAYMENT | BD37: =BD16 -> 32680 | BE37: =BD37-BD16 -> 0 | BF37: =BE37*BF17 -> 0
B38: ='Pricing Trends'!R44 -> 0 | C38: ='Pricing Trends'!S44 -> 0 | D38: ='Pricing Trends'!U44 -> 0 | E38: FALSE | I38: note: Prices used @ Recent purchases -- Palm Oil @ Local Purchase + Soya and Canola @ Foreign Purchase | AE38: Angie | AG38: Bottle 350mL | AH38: Price Increase Chat | AK38: 350mL - Price Increase Chat | AP38: 4.1 | AZ38: =AP38 -> 4.1
B39: ='Pricing Trends'!R45 -> RBD PALM OLEIN (FOREIGN) | C39: ='Pricing Trends'!S45 -> 0 | D39: ='Pricing Trends'!U45 -> 82.366515 | E39: FALSE | I39: Price of boxes @ most recent purchase on May | AE39: Wennie-Receipts | AF39: 46129 | AG39: Flour | AH39: Mabuhay Interflour Inc. | AI39: DELIVERY RECEIPT | AJ39: 1012433 | AK39: CHOPSTICKS SNF PP BAG 25KG | AL39: 25kg | AM39: 1001700 | AN39: 400 | AO39: bags | AP39: =AQ39/AN39 -> 818.27675 | AQ39: 327310.7 | AT39: =AP39/25 -> 32.73107 | AX39: =AT39 -> 32.73107
B40: ='Pricing Trends'!R46 -> RBD PALM OLEIN (FOREIGN) | C40: ='Pricing Trends'!S46 -> 0 | D40: ='Pricing Trends'!U46 -> 74.65686 | E40: FALSE | I40: Prices of bottles @ most recent purchase | AE40: System | AF40: 46165 | AG40: Pickup - Palm | AH40: Angel Castro | AI40: System | AJ40: NT-005114 | AK40: PALM 5/16 Purchase Pickup | AN40: =AN33 -> 30410 | AO40: =AO33 -> KG | AQ40: 7000 | AU40: =AU33 -> 34557.924 | AZ40: =AQ40/AU40 -> 0.20255846
...

Sheet Validation
B2: BLENDING PRICE COMPARISON PER CODE
B4: Type | C4: Code | D4: Oil | E4: Conca | F4: Mix | G4: T Price | H4: 350ml | I4: 500ml | J4: 1L | K4: 2L | L4: 4L | M4: 180ml | N4: 300ml | O4: 17KG | Q4: PALM OLEIN CODE
B5: PALM OLEIN | C5: BAS | D5: RBD SOYA BEAN OIL | E5: =C5&D5 -> BASRBD SOYA BEAN OIL | F5: 0.4 | G5: =SUMIFS('Pricing Trends'!U:U,'Pricing Trends'!R:R,Validation!D5,'Pricing Trends'!P:P,"TRUE")/COUNTIFS('Pricing Trends'!R:R,Validation!D5,'Pricing Trends'!P:P,"TRUE") -> 69.078872 | H5: =G5*F5*0.35 -> 9.6710421 | I5: =G5*F5*0.5 -> 13.815774 | J5: =G5*F5 -> 27.631549 | K5: =J5*2 -> 55.263098 | L5: =K5*2 -> 110.5262 | M5: =J5*0.18 -> 4.9736788 | N5: =J5*0.3 -> 8.2894646 | O5: =J5*15.66*1.1364 -> 491.7317 | Q5: =C5 -> BAS
C6: BAS | D6: RBD PALM OLEIN (LOCAL) | E6: =C6&D6 -> BASRBD PALM OLEIN (LOCAL) | F6: 0.6 | G6: =SUMIFS('Pricing Trends'!U:U,'Pricing Trends'!R:R,Validation!D6,'Pricing Trends'!P:P,"TRUE")/COUNTIFS('Pricing Trends'!R:R,Validation!D6,'Pricing Trends'!P:P,"TRUE") -> #DIV/0! | H6: =G6*F6*0.35 -> #DIV/0! | I6: =G6*F6*0.5 -> #DIV/0! | J6: =G6*F6 -> #DIV/0! | K6: =J6*2 -> #DIV/0! | L6: =K6*2 -> #DIV/0! | M6: =J6*0.18 -> #DIV/0! | N6: =J6*0.3 -> #DIV/0! | O6: =J6*15.66*1.1364 -> #DIV/0! | Q6: =C8 -> BTC
H7: =SUM(H5:H6) -> #DIV/0! | I7: =SUM(I5:I6) -> #DIV/0! | J7: =SUM(J5:J6) -> #DIV/0! | K7: =SUM(K5:K6) -> #DIV/0! | L7: =SUM(L5:L6) -> #DIV/0! | M7: =SUM(M5:M6) -> #DIV/0! | N7: =SUM(N5:N6) -> #DIV/0! | O7: =SUM(O5:O6) -> #DIV/0! | Q7: =C11 -> FD3
C8: BTC | D8: RBD SOYA BEAN OIL | E8: =C8&D8 -> BTCRBD SOYA BEAN OIL | F8: 0.3 | G8: =SUMIFS('Pricing Trends'!U:U,'Pricing Trends'!R:R,Validation!D8,'Pricing Trends'!P:P,"TRUE")/COUNTIFS('Pricing Trends'!R:R,Validation!D8,'Pricing Trends'!P:P,"TRUE") -> 69.078872 | H8: =G8*F8*0.35 -> 7.2532815 | I8: =G8*F8*0.5 -> 10.361831 | J8: =G8*F8 -> 20.723662 | K8: =J8*2 -> 41.447323 | L8: =K8*2 -> 82.894646 | M8: =J8*0.18 -> 3.7302591 | N8: =J8*0.3 -> 6.2170985 | O8: =J8*15.66*1.1364 -> 368.79878 | Q8: =C14 -> BAS.F64
C9: BTC | D9: RBD PALM OLEIN (LOCAL) | E9: =C9&D9 -> BTCRBD PALM OLEIN (LOCAL) | F9: 0.7 | G9: =SUMIFS('Pricing Trends'!U:U,'Pricing Trends'!R:R,Validation!D9,'Pricing Trends'!P:P,"TRUE")/COUNTIFS('Pricing Trends'!R:R,Validation!D9,'Pricing Trends'!P:P,"TRUE") -> #DIV/0! | H9: =G9*F9*0.35 -> #DIV/0! | I9: =G9*F9*0.5 -> #DIV/0! | J9: =G9*F9 -> #DIV/0! | K9: =J9*2 -> #DIV/0! | L9: =K9*2 -> #DIV/0! | M9: =J9*0.18 -> #DIV/0! | N9: =J9*0.3 -> #DIV/0! | O9: =J9*15.66*1.1364 -> #DIV/0! | Q9: =C17 -> BAS.F73
H10: =SUM(H8:H9) -> #DIV/0! | I10: =SUM(I8:I9) -> #DIV/0! | J10: =SUM(J8:J9) -> #DIV/0! | K10: =SUM(K8:K9) -> #DIV/0! | L10: =SUM(L8:L9) -> #DIV/0! | M10: =SUM(M8:M9) -> #DIV/0! | N10: =SUM(N8:N9) -> #DIV/0! | O10: =SUM(O8:O9) -> #DIV/0! | Q10: =C21 -> BAS.F82
C11: FD3 | D11: RBD SOYA BEAN OIL | E11: =C11&D11 -> FD3RBD SOYA BEAN OIL | F11: 0.2 | G11: =SUMIFS('Pricing Trends'!U:U,'Pricing Trends'!R:R,Validation!D11,'Pricing Trends'!P:P,"TRUE")/COUNTIFS('Pricing Trends'!R:R,Validation!D11,'Pricing Trends'!P:P,"TRUE") -> 69.078872 | H11: =G11*F11*0.35 -> 4.835521 | I11: =G11*F11*0.5 -> 6.9078872 | J11: =G11*F11 -> 13.815774 | K11: =J11*2 -> 27.631549 | L11: =K11*2 -> 55.263098 | M11: =J11*0.18 -> 2.4868394 | N11: =J11*0.3 -> 4.1447323 | O11: =J11*15.66*1.1364 -> 245.86585 | Q11: =C23 -> PALM.100
C12: FD3 | D12: RBD PALM OLEIN (LOCAL) | E12: =C12&D12 -> FD3RBD PALM OLEIN (LOCAL) | F12: 0.8 | G12: =SUMIFS('Pricing Trends'!U:U,'Pricing Trends'!R:R,Validation!D12,'Pricing Trends'!P:P,"TRUE")/COUNTIFS('Pricing Trends'!R:R,Validation!D12,'Pricing Trends'!P:P,"TRUE") -> #DIV/0! | H12: =G12*F12*0.35 -> #DIV/0! | I12: =G12*F12*0.5 -> #DIV/0! | J12: =G12*F12 -> #DIV/0! | K12: =J12*2 -> #DIV/0! | L12: =K12*2 -> #DIV/0! | M12: =J12*0.18 -> #DIV/0! | N12: =J12*0.3 -> #DIV/0! | O12: =J12*15.66*1.1364 -> #DIV/0! | Q12: =C25 -> PALMF.100
H13: =SUM(H11:H12) -> #DIV/0! | I13: =SUM(I11:I12) -> #DIV/0! | J13: =SUM(J11:J12) -> #DIV/0! | K13: =SUM(K11:K12) -> #DIV/0! | L13: =SUM(L11:L12) -> #DIV/0! | M13: =SUM(M11:M12) -> #DIV/0! | N13: =SUM(N11:N12) -> #DIV/0! | O13: =SUM(O11:O12) -> #DIV/0!
C14: BAS.F64 | D14: RBD SOYA BEAN OIL | E14: =C14&D14 -> BAS.F64RBD SOYA BEAN OIL | F14: 0.4 | G14: =SUMIFS('Pricing Trends'!U:U,'Pricing Trends'!R:R,Validation!D14,'Pricing Trends'!P:P,"TRUE")/COUNTIFS('Pricing Trends'!R:R,Validation!D14,'Pricing Trends'!P:P,"TRUE") -> 69.078872 | H14: =G14*F14*0.35 -> 9.6710421 | I14: =G14*F14*0.5 -> 13.815774 | J14: =G14*F14 -> 27.631549 | K14: =J14*2 -> 55.263098 | L14: =K14*2 -> 110.5262 | M14: =J14*0.18 -> 4.9736788 | N14: =J14*0.3 -> 8.2894646 | O14: =J14*15.66*1.1364 -> 491.7317
C15: BAS.F64 | D15: RBD PALM OLEIN (FOREIGN) | E15: =C15&D15 -> BAS.F64RBD PALM OLEIN (FOREIGN) | F15: 0.6 | G15: =SUMIFS('Pricing Trends'!U:U,'Pricing Trends'!R:R,Validation!D15,'Pricing Trends'!P:P,"TRUE")/COUNTIFS('Pricing Trends'!R:R,Validation!D15,'Pricing Trends'!P:P,"TRUE") -> 60.65316 | H15: =G15*F15*0.35 -> 12.737164 | I15: =G15*F15*0.5 -> 18.195948 | J15: =G15*F15 -> 36.391896 | K15: =J15*2 -> 72.783792 | L15: =K15*2 -> 145.56758 | M15: =J15*0.18 -> 6.5505413 | N15: =J15*0.3 -> 10.917569 | O15: =J15*15.66*1.1364 -> 647.63105
H16: =SUM(H14:H15) -> 22.408206 | I16: =SUM(I14:I15) -> 32.011722 | J16: =SUM(J14:J15) -> 64.023445 | K16: =SUM(K14:K15) -> 128.04689 | L16: =SUM(L14:L15) -> 256.09378 | M16: =SUM(M14:M15) -> 11.52422 | N16: =SUM(N14:N15) -> 19.207033 | O16: =SUM(O14:O15) -> 1139.3628
C17: BAS.F73 | D17: RBD SOYA BEAN OIL | E17: =C17&D17 -> BAS.F73RBD SOYA BEAN OIL | F17: 0.3 | G17: =SUMIFS('Pricing Trends'!U:U,'Pricing Trends'!R:R,Validation!D17,'Pricing Trends'!P:P,"TRUE")/COUNTIFS('Pricing Trends'!R:R,Validation!D17,'Pricing Trends'!P:P,"TRUE") -> 69.078872 | H17: =G17*F17*0.35 -> 7.2532815 | I17: =G17*F17*0.5 -> 10.361831 | J17: =G17*F17 -> 20.723662 | K17: =J17*2 -> 41.447323 | L17: =K17*2 -> 82.894646 | M17: =J17*0.18 -> 3.7302591 | N17: =J17*0.3 -> 6.2170985 | O17: =J17*15.66*1.1364 -> 368.79878
C18: BAS.F73 | D18: RBD PALM OLEIN (FOREIGN) | E18: =C18&D18 -> BAS.F73RBD PALM OLEIN (FOREIGN) | F18: 0.7 | G18: =SUMIFS('Pricing Trends'!U:U,'Pricing Trends'!R:R,Validation!D18,'Pricing Trends'!P:P,"TRUE")/COUNTIFS('Pricing Trends'!R:R,Validation!D18,'Pricing Trends'!P:P,"TRUE") -> 60.65316 | H18: =G18*F18*0.35 -> 14.860024 | I18: =G18*F18*0.5 -> 21.228606 | J18: =G18*F18 -> 42.457212 | K18: =J18*2 -> 84.914424 | L18: =K18*2 -> 169.82885 | M18: =J18*0.18 -> 7.6422982 | N18: =J18*0.3 -> 12.737164 | O18: =J18*15.66*1.1364 -> 755.56956
H19: =SUM(H17:H18) -> 22.113306 | I19: =SUM(I17:I18) -> 31.590437 | J19: =SUM(J17:J18) -> 63.180874 | K19: =SUM(K17:K18) -> 126.36175 | L19: =SUM(L17:L18) -> 252.72349 | M19: =SUM(M17:M18) -> 11.372557 | N19: =SUM(N17:N18) -> 18.954262 | O19: =SUM(O17:O18) -> 1124.3683
C20: BAS.F82 | D20: RBD SOYA BEAN OIL | E20: =C20&D20 -> BAS.F82RBD SOYA BEAN OIL | F20: 0.2 | G20: =SUMIFS('Pricing Trends'!U:U,'Pricing Trends'!R:R,Validation!D20,'Pricing Trends'!P:P,"TRUE")/COUNTIFS('Pricing Trends'!R:R,Validation!D20,'Pricing Trends'!P:P,"TRUE") -> 69.078872 | H20: =G20*F20*0.35 -> 4.835521 | I20: =G20*F20*0.5 -> 6.9078872 | J20: =G20*F20 -> 13.815774 | K20: =J20*2 -> 27.631549 | L20: =K20*2 -> 55.263098 | M20: =J20*0.18 -> 2.4868394 | N20: =J20*0.3 -> 4.1447323 | O20: =J20*15.66*1.1364 -> 245.86585
C21: BAS.F82 | D21: RBD PALM OLEIN (FOREIGN) | E21: =C21&D21 -> BAS.F82RBD PALM OLEIN (FOREIGN) | F21: 0.8 | G21: =SUMIFS('Pricing Trends'!U:U,'Pricing Trends'!R:R,Validation!D21,'Pricing Trends'!P:P,"TRUE")/COUNTIFS('Pricing Trends'!R:R,Validation!D21,'Pricing Trends'!P:P,"TRUE") -> 60.65316 | H21: =G21*F21*0.35 -> 16.982885 | I21: =G21*F21*0.5 -> 24.261264 | J21: =G21*F21 -> 48.522528 | K21: =J21*2 -> 97.045056 | L21: =K21*2 -> 194.09011 | M21: =J21*0.18 -> 8.734055 | N21: =J21*0.3 -> 14.556758 | O21: =J21*15.66*1.1364 -> 863.50807
H22: =SUM(H20:H21) -> 21.818406 | I22: =SUM(I20:I21) -> 31.169151 | J22: =SUM(J20:J21) -> 62.338302 | K22: =SUM(K20:K21) -> 124.6766 | L22: =SUM(L20:L21) -> 249.35321 | M22: =SUM(M20:M21) -> 11.220894 | N22: =SUM(N20:N21) -> 18.701491 | O22: =SUM(O20:O21) -> 1109.3739
C23: PALM.100 | D23: RBD PALM OLEIN (LOCAL) | E23: =C23&D23 -> PALM.100RBD PALM OLEIN (LOCAL) | F23: 1 | G23: =SUMIFS('Pricing Trends'!U:U,'Pricing Trends'!R:R,Validation!D23,'Pricing Trends'!P:P,"TRUE")/COUNTIFS('Pricing Trends'!R:R,Validation!D23,'Pricing Trends'!P:P,"TRUE") -> #DIV/0! | H23: =G23*F23*0.35 -> #DIV/0! | I23: =G23*F23*0.5 -> #DIV/0! | J23: =G23*F23 -> #DIV/0! | K23: =J23*2 -> #DIV/0! | L23: =K23*2 -> #DIV/0! | M23: =J23*0.18 -> #DIV/0! | N23: =J23*0.3 -> #DIV/0! | O23: =J23*15.66*1.1364 -> #DIV/0!
H24: =SUM(H23) -> #DIV/0! | I24: =SUM(I23) -> #DIV/0! | J24: =SUM(J23) -> #DIV/0! | K24: =SUM(K23) -> #DIV/0! | L24: =SUM(L23) -> #DIV/0! | M24: =SUM(M23) -> #DIV/0! | N24: =SUM(N23) -> #DIV/0! | O24: =SUM(O23) -> #DIV/0!
C25: PALMF.100 | D25: RBD PALM OLEIN (FOREIGN) | E25: =C25&D25 -> PALMF.100RBD PALM OLEIN (FOREIGN) | F25: 1 | G25: =SUMIFS('Pricing Trends'!U:U,'Pricing Trends'!R:R,Validation!D25,'Pricing Trends'!P:P,"TRUE")/COUNTIFS('Pricing Trends'!R:R,Validation!D25,'Pricing Trends'!P:P,"TRUE") -> 60.65316 | H25: =G25*F25*0.35 -> 21.228606 | I25: =G25*F25*0.5 -> 30.32658 | J25: =G25*F25 -> 60.65316 | K25: =J25*2 -> 121.30632 | L25: =K25*2 -> 242.61264 | M25: =J25*0.18 -> 10.917569 | N25: =J25*0.3 -> 18.195948 | O25: =J25*15.66*1.1364 -> 1079.3851
H26: =SUM(H25:H25) -> 21.228606 | I26: =SUM(I25:I25) -> 30.32658 | J26: =SUM(J25:J25) -> 60.65316 | K26: =SUM(K25:K25) -> 121.30632 | L26: =SUM(L25:L25) -> 242.61264 | M26: =SUM(M25:M25) -> 10.917569 | N26: =SUM(N25:N25) -> 18.195948 | O26: =SUM(O25:O25) -> 1079.3851
B27: CANOLEIN | C27: CANF.82 | D27: RBD CANOLA OIL | E27: =C27&D27 -> CANF.82RBD CANOLA OIL | F27: 0.8 | G27: =SUMIFS('Pricing Trends'!U:U,'Pricing Trends'!R:R,Validation!D27,'Pricing Trends'!P:P,"TRUE")/COUNTIFS('Pricing Trends'!R:R,Validation!D27,'Pricing Trends'!P:P,"TRUE") -> 83.220041 | J27: =G27*F27 -> 66.576033 | K27: =J27*2 -> 133.15207 | L27: =K27*2 -> 266.30413 | M27: =J27*0.18 -> 11.983686 | N27: =J27*0.3 -> 19.97281 | O27: =J27*15.66*1.1364 -> 1184.7887 | Q27: CANOLEIN CODE
C28: CANF.82 | D28: RBD PALM OLEIN (FOREIGN) | E28: =C28&D28 -> CANF.82RBD PALM OLEIN (FOREIGN) | F28: 0.2 | G28: =SUMIFS('Pricing Trends'!U:U,'Pricing Trends'!R:R,Validation!D28,'Pricing Trends'!P:P,"TRUE")/COUNTIFS('Pricing Trends'!R:R,Validation!D28,'Pricing Trends'!P:P,"TRUE") -> 60.65316 | J28: =G28*F28 -> 12.130632 | K28: =J28*2 -> 24.261264 | L28: =K28*2 -> 48.522528 | M28: =J28*0.18 -> 2.1835138 | N28: =J28*0.3 -> 3.6391896 | O28: =J28*15.66*1.1364 -> 215.87702 | Q28: =C27 -> CANF.82
J29: =SUM(J27:J28) -> 78.706665 | K29: =SUM(K27:K28) -> 157.41333 | L29: =SUM(L27:L28) -> 314.82666 | M29: =SUM(M27:M28) -> 14.1672 | N29: =SUM(N27:N28) -> 23.612 | O29: =SUM(O27:O28) -> 1400.6657 | Q29: =C30 -> CAN.100
C30: CAN.100 | D30: RBD CANOLA OIL | E30: =C30&D30 -> CAN.100RBD CANOLA OIL | F30: 1 | G30: =SUMIFS('Pricing Trends'!U:U,'Pricing Trends'!R:R,Validation!D30,'Pricing Trends'!P:P,"TRUE")/COUNTIFS('Pricing Trends'!R:R,Validation!D30,'Pricing Trends'!P:P,"TRUE") -> 83.220041 | J30: =G30*F30 -> 83.220041 | K30: =J30*2 -> 166.44008 | L30: =K30*2 -> 332.88017 | M30: =J30*0.18 -> 14.979607 | N30: =J30*0.3 -> 24.966012 | O30: =J30*15.66*1.1364 -> 1480.9859
J31: =SUM(J30) -> 83.220041 | K31: =SUM(K30) -> 166.44008 | L31: =SUM(L30) -> 332.88017 | M31: =SUM(M30) -> 14.979607 | N31: =SUM(N30) -> 24.966012 | O31: =SUM(O30) -> 1480.9859
B32: SOYA OIL | C32: SOYF.73 | D32: RBD SOYA BEAN OIL | E32: =C32&D32 -> SOYF.73RBD SOYA BEAN OIL | F32: 0.7 | G32: =SUMIFS('Pricing Trends'!U:U,'Pricing Trends'!R:R,Validation!D32,'Pricing Trends'!P:P,"TRUE")/COUNTIFS('Pricing Trends'!R:R,Validation!D32,'Pricing Trends'!P:P,"TRUE") -> 69.078872 | J32: =G32*F32 -> 48.35521 | K32: =J32*2 -> 96.710421 | L32: =K32*2 -> 193.42084 | M32: =J32*0.18 -> 8.7039379 | N32: =J32*0.3 -> 14.506563 | O32: =J32*15.66*1.1364 -> 860.53048 | Q32: SOYA OIL CODE
C33: SOYF.73 | D33: RBD PALM OLEIN (FOREIGN) | E33: =C33&D33 -> SOYF.73RBD PALM OLEIN (FOREIGN) | F33: 0.3 | G33: =SUMIFS('Pricing Trends'!U:U,'Pricing Trends'!R:R,Validation!D33,'Pricing Trends'!P:P,"TRUE")/COUNTIFS('Pricing Trends'!R:R,Validation!D33,'Pricing Trends'!P:P,"TRUE") -> 60.65316 | J33: =G33*F33 -> 18.195948 | K33: =J33*2 -> 36.391896 | L33: =K33*2 -> 72.783792 | M33: =J33*0.18 -> 3.2752706 | N33: =J33*0.3 -> 5.4587844 | O33: =J33*15.66*1.1364 -> 323.81553 | Q33: =C32 -> SOYF.73
J34: =SUM(J32:J33) -> 66.551158 | K34: =SUM(K32:K33) -> 133.10232 | L34: =SUM(L32:L33) -> 266.20463 | M34: =SUM(M32:M33) -> 11.979208 | N34: =SUM(N32:N33) -> 19.965347 | O34: =SUM(O32:O33) -> 1184.346 | Q34: =C35 -> SOYF.82
C35: SOYF.82 | D35: RBD SOYA BEAN OIL | E35: =C35&D35 -> SOYF.82RBD SOYA BEAN OIL | F35: 0.8 | G35: =SUMIFS('Pricing Trends'!U:U,'Pricing Trends'!R:R,Validation!D35,'Pricing Trends'!P:P,"TRUE")/COUNTIFS('Pricing Trends'!R:R,Validation!D35,'Pricing Trends'!P:P,"TRUE") -> 69.078872 | J35: =G35*F35 -> 55.263098 | K35: =J35*2 -> 110.5262 | L35: =K35*2 -> 221.05239 | M35: =J35*0.18 -> 9.9473576 | N35: =J35*0.3 -> 16.578929 | O35: =J35*15.66*1.1364 -> 983.46341 | Q35: =C38 -> SOY.100
C36: SOYF.82 | D36: RBD PALM OLEIN (FOREIGN) | E36: =C36&D36 -> SOYF.82RBD PALM OLEIN (FOREIGN) | F36: 0.2 | G36: =SUMIFS('Pricing Trends'!U:U,'Pricing Trends'!R:R,Validation!D36,'Pricing Trends'!P:P,"TRUE")/COUNTIFS('Pricing Trends'!R:R,Validation!D36,'Pricing Trends'!P:P,"TRUE") -> 60.65316 | J36: =G36*F36 -> 12.130632 | K36: =J36*2 -> 24.261264 | L36: =K36*2 -> 48.522528 | M36: =J36*0.18 -> 2.1835138 | N36: =J36*0.3 -> 3.6391896 | O36: =J36*15.66*1.1364 -> 215.87702
J37: =SUM(J35:J36) -> 67.39373 | K37: =SUM(K35:K36) -> 134.78746 | L37: =SUM(L35:L36) -> 269.57492 | M37: =SUM(M35:M36) -> 12.130871 | N37: =SUM(N35:N36) -> 20.218119 | O37: =SUM(O35:O36) -> 1199.3404
C38: SOY.100 | D38: RBD SOYA BEAN OIL | E38: =C38&D38 -> SOY.100RBD SOYA BEAN OIL | F38: 1 | G38: =SUMIFS('Pricing Trends'!U:U,'Pricing Trends'!R:R,Validation!D38,'Pricing Trends'!P:P,"TRUE")/COUNTIFS('Pricing Trends'!R:R,Validation!D38,'Pricing Trends'!P:P,"TRUE") -> 69.078872 | J38: =G38*F38 -> 69.078872 | K38: =J38*2 -> 138.15774 | L38: =K38*2 -> 276.31549 | M38: =J38*0.18 -> 12.434197 | N38: =J38*0.3 -> 20.723662 | O38: =J38*15.66*1.1364 -> 1229.3293
J39: =SUM(J38:J38) -> 69.078872 | K39: =SUM(K38:K38) -> 138.15774 | L39: =SUM(L38:L38) -> 276.31549 | M39: =SUM(M38:M38) -> 12.434197 | N39: =SUM(N38:N38) -> 20.723662 | O39: =SUM(O38:O38) -> 1229.3293
B40: VEGETABLE OIL | C40: VG100 | D40: RBD COCONUT OIL | E40: =C40&D40 -> VG100RBD COCONUT OIL | F40: 1 | G40: =SUMIFS('Pricing Trends'!U:U,'Pricing Trends'!R:R,Validation!D40,'Pricing Trends'!P:P,"TRUE")/COUNTIFS('Pricing Trends'!R:R,Validation!D40,'Pricing Trends'!P:P,"TRUE") -> 85.357269 | J40: =G40*F40 -> 85.357269 | K40: =J40*2 -> 170.71454 | L40: =K40*2 -> 341.42907 | M40: =J40*0.18 -> 15.364308 | N40: =J40*0.3 -> 25.607181 | O40: =J40*1.1364*15.66 -> 1519.02
J41: =SUM(J40:J40) -> 85.357269 | K41: =SUM(K40:K40) -> 170.71454 | L41: =SUM(L40:L40) -> 341.42907 | M41: =SUM(M40:M40) -> 15.364308 | N41: =SUM(N40:N40) -> 25.607181 | O41: =SUM(O40:O40) -> 1519.02

Sheet PALM
B2: 1ST ORDER | M2: 2ND ORDER | X2: 3RD ORDER | AI2: 4TH ORDER | AT2: 5TH ORDER | BE2: 6TH ORDER | BP2: 7TH ORDER | CA2: 8TH ORDER | CL2: CP10 | CW2: FOR OSAVE | DI2: PENDING 01022025
B4: SUPPLIER INFORMATION | H4: PAYMENT SUMMARY AND COST PER UNIT (Formulated Table) | M4: SUPPLIER INFORMATION | S4: PAYMENT SUMMARY AND COST PER UNIT (Formulated Table) | X4: SUPPLIER INFORMATION | AD4: PAYMENT SUMMARY AND COST PER UNIT (Formulated Table) | AI4: SUPPLIER INFORMATION | AO4: PAYMENT SUMMARY AND COST PER UNIT (Formulated Table) | AT4: SUPPLIER INFORMATION | AZ4: PAYMENT SUMMARY AND COST PER UNIT (Formulated Table) | BE4: SUPPLIER INFORMATION | BK4: PAYMENT SUMMARY AND COST PER UNIT (Formulated Table) | BP4: SUPPLIER INFORMATION | BV4: PAYMENT SUMMARY AND COST PER UNIT (Formulated Table) | CA4: SUPPLIER INFORMATION | CG4: PAYMENT SUMMARY AND COST PER UNIT (Formulated Table) | CL4: SUPPLIER INFORMATION | CR4: PAYMENT SUMMARY AND COST PER UNIT (Formulated Table) | CW4: SUPPLIER INFORMATION | DC4: PAYMENT SUMMARY AND COST PER UNIT (Formulated Table) | DI4: SUPPLIER INFORMATION | DO4: PAYMENT SUMMARY AND COST PER UNIT (Formulated Table)
B5: Supplier: | C5: Cornerstone APAC (S) PTE LTD | H5: Description | I5: Amount | J5: CPU (KG) | K5: CPU (LTR) | M5: Supplier: | N5: MAC World Globality Reliable | S5: Description | T5: Amount | U5: CPU (KG) | V5: CPU (LTR) | X5: Supplier: | Y5: Cornerstone APAC (S) PTE LTD | AD5: Description | AE5: Amount | AF5: CPU (KG) | AG5: CPU (LTR) | AI5: Supplier: | AJ5: Cornerstone APAC (S) PTE LTD | AO5: Description | AP5: Amount | AQ5: CPU (KG) | AR5: CPU (LTR) | AT5: Supplier: | AU5: MOI INTERNATIONAL (SINGAPORE) PTE. LTD. | AZ5: Description | BA5: Amount | BB5: CPU (KG) | BC5: CPU (LTR) | BE5: Supplier: | BF5: MOI INTERNATIONAL (SINGAPORE) PTE. LTD. | BK5: Description | BL5: Amount | BM5: CPU (KG) | BN5: CPU (LTR) | BP5: Supplier: | BQ5: MOI INTERNATIONAL (SINGAPORE) PTE. LTD. | BV5: Description | BW5: Amount | BX5: CPU (KG) | BY5: CPU (LTR) | CA5: Supplier: | CB5: MOI INTERNATIONAL (SINGAPORE) PTE. LTD. | CG5: Description | CH5: Amount | CI5: CPU (KG) | CJ5: CPU (LTR) | CL5: Supplier: | CM5: MOI INTERNATIONAL (SINGAPORE) PTE. LTD. | CR5: Description | CS5: Amount | CT5: CPU (KG) | CU5: CPU (LTR) | CW5: Supplier: | CX5: MOI INTERNATIONAL (SINGAPORE) PTE. LTD. | DC5: Description | DD5: Amount | DE5: CPU (KG) | DF5: CPU (LTR) | DI5: Supplier: | DJ5: MOI INTERNATIONAL (SINGAPORE) PTE. LTD. | DO5: Description | DP5: Amount | DQ5: CPU (KG) | DR5: CPU (LTR)
B6: Address: | C6: 190 Middle Road #19-05 Fortune Centre Singapore | H6: As per Foreign Cost | I6: =F22+F38 -> 1802264.5 | J6: =I6/D16 -> 87.108 | K6: =I6/F17 -> 76.652587 | M6: Address: | S6: As per Foreign Cost | T6: =Q22+Q38 -> 1270386 | U6: =T6/O16 -> 59.475 | V6: =T6/Q17 -> 52.336325 | X6: Address: | Y6: 190 Middle Road #19-05 Fortune Centre Singapore | AD6: As per Foreign Cost | AE6: =AB22+AB38 -> 1434720 | AF6: =AE6/Z16 -> 67.803403 | AG6: =AE6/AB17 -> 59.665085 | AI6: Address: | AJ6: 190 Middle Road #19-05 Fortune Centre Singapore | AO6: As per Foreign Cost | AP6: =AM22+AM38 -> 1413467.6 | AQ6: =AP6/AK16 -> 66.673 | AR6: =AP6/AM17 -> 58.670363 | AT6: Address: | AU6: 5, International Business Park, #04-00 Mewah Building, Singapore | AZ6: As per Foreign Cost | BA6: =AX22+AX38 -> 1320930.6 | BB6: =BA6/AV16 -> 62.22 | BC6: =BA6/AX17 -> 54.751848 | BE6: Address: | BF6: 5, International Business Park, #04-00 Mewah Building, Singapore | BK6: As per Foreign Cost | BL6: =BI22+BI38 -> 1337730 | BM6: =BL6/BG16 -> 62.22 | BN6: =BL6/BI17 -> 54.751848 | BP6: Address: | BQ6: 5, International Business Park, #04-00 Mewah Building, Singapore | BV6: As per Foreign Cost | BW6: =BT22+BT38 -> 1350845 | BX6: =BW6/BR16 -> 62.83 | BY6: =BW6/BT17 -> 55.288631 | CA6: Address: | CB6: 5, International Business Park, #04-00 Mewah Building, Singapore | CG6: As per Foreign Cost | CH6: =CE22+CE38 -> 1381558.5 | CI6: =CH6/CC16 -> 64.05 | CJ6: =CH6/CE17 -> 56.362196 | CL6: Address: | CM6: 5, International Business Park, #04-00 Mewah Building, Singapore | CR6: As per Foreign Cost | CS6: =CP22+CP38 -> 1390190 | CT6: =CS6/CN16 -> 64.66 | CU6: =CS6/CP17 -> 56.898979 | CW6: Address: | CX6: 5, International Business Park, #04-00 Mewah Building, Singapore | DC6: As per Foreign Cost | DD6: =DA22+DA38 -> 1578924 | DE6: =DD6/CY16 -> 73.2 | DF6: =DD6/DA17 -> 64.413939 | DI6: Address: | DJ6: 5, International Business Park, #04-00 Mewah Building, Singapore | DO6: As per Foreign Cost | DP6: =DM22+DM38 -> 1830000 | DQ6: =DP6/DK16 -> 84.840056 | DR6: =DP6/DM17 -> 74.65686
B7: Shippine Line: | C7: Save and Best Cargo Logistic Corp | H7: As per Local Cost | I7: =K35+J21 -> 335246.54 | J7: =I7/D16 -> 16.203313 | K7: =I7/F17 -> 14.258459 | M7: Shippine Line: | N7: Save and Best Cargo Logistic Corp | S7: As per Local Cost | T7: =V35+U21 -> 306172.07 | U7: =T7/O16 -> 14.333898 | V7: =T7/Q17 -> 12.613427 | X7: Shippine Line: | Y7: Save and Best Cargo Logistic Corp | AD7: As per Local Cost | AE7: =AG35+AF21 -> 311309 | AF7: =AE7/Z16 -> 14.712146 | AG7: =AE7/AB17 -> 12.946274 | AI7: Shippine Line: | AJ7: Save and Best Cargo Logistic Corp | AO7: As per Local Cost | AP7: =AR35+AQ21 -> 308737.46 | AQ7: =AP7/AK16 -> 14.563088 | AR7: =AP7/AM17 -> 12.815107 | AT7: Shippine Line: | AU7: Save and Best Cargo Logistic Corp | AZ7: As per Local Cost | BA7: =BC35+BB21 -> 307159.74 | BB7: =BA7/AV16 -> 14.468193 | BC7: =BA7/AX17 -> 12.731603 | BE7: Shippine Line: | BF7: Save and Best Cargo Logistic Corp | BK7: As per Local Cost | BL7: =BN35+BM21 -> 309938.19 | BM7: =BL7/BG16 -> 14.41573 | BN7: =BL7/BI17 -> 12.685436 | BP7: Shippine Line: | BQ7: Save and Best Cargo Logistic Corp | BV7: As per Local Cost | BW7: =BY35+BX21 -> 316450.67 | BX7: =BW7/BR16 -> 14.718636 | BY7: =BW7/BT17 -> 12.951985 | CA7: Shippine Line: | CB7: Save and Best Cargo Logistic Corp | CG7: As per Local Cost | CH7: =CJ35+CI21 -> 320231.29 | CI7: =CH7/CC16 -> 14.846142 | CJ7: =CH7/CE17 -> 13.064187 | CL7: Shippine Line: | CM7: Save and Best Cargo Logistic Corp | CR7: As per Local Cost | CS7: =CU35+CT21 -> 316450.67 | CT7: =CS7/CN16 -> 14.718636 | CU7: =CS7/CP17 -> 12.951985 | CW7: Shippine Line: | CX7: Save and Best Cargo Logistic Corp | DC7: As per Local Cost | DD7: =DF35+DE21 -> 320231.29 | DE7: =DD7/CY16 -> 14.846142 | DF7: =DD7/DA17 -> 13.064187 | DI7: Shippine Line: | DJ7: Save and Best Cargo Logistic Corp | DO7: As per Local Cost | DP7: =DR35+DQ21 -> 320231.29 | DQ7: =DP7/DK16 -> 14.846142 | DR7: =DP7/DM17 -> 13.064187
B8: Date: | C8: 44788 | E8: Date Received: | F8: 44838 | H8: As per Gross of BOC | I8: =I6+I7 -> 2137511.1 | J8: =I8/D16 -> 103.31131 | K8: =I8/F17 -> 90.911046 | M8: Date: | N8: 45202 | P8: Date Received: | Q8: 45234 | S8: As per Gross of BOC | T8: =T6+T7 -> 1576558.1 | U8: =T8/O16 -> 73.808898 | V8: =T8/Q17 -> 64.949752 | X8: Date: | Y8: 45161 | AA8: Date Received: | AB8: 45244 | AD8: As per Gross of BOC | AE8: =AE6+AE7 -> 1746029 | AF8: =AE8/Z16 -> 82.515548 | AG8: =AE8/AB17 -> 72.611359 | AI8: Date: | AJ8: 45217 | AL8: Date Received: | AM8: 45244 | AO8: As per Gross of BOC | AP8: =AP6+AP7 -> 1722205.1 | AQ8: =AP8/AK16 -> 81.236088 | AR8: =AP8/AM17 -> 71.48547 | AT8: Date: | AU8: 45279 | AW8: Date Received: | AX8: 45314 | AZ8: As per Gross of BOC | BA8: =BA6+BA7 -> 1628090.3 | BB8: =BA8/AV16 -> 76.688193 | BC8: =BA8/AX17 -> 67.48345 | BE8: Date: | BF8: 45420 | BH8: Date Received: | BI8: 45494 | BK8: As per Gross of BOC | BL8: =BL6+BL7 -> 1647668.2 | BM8: =BL8/BG16 -> 76.63573 | BN8: =BL8/BI17 -> 67.437284 | BP8: Date: | BQ8: 45433 | BS8: Date Received: | BT8: 45517 | BV8: As per Gross of BOC | BW8: =BW6+BW7 -> 1667295.7 | BX8: =BW8/BR16 -> 77.548636 | BY8: =BW8/BT17 -> 68.240616 | CA8: Date: | CB8: 45515 | CD8: Date Received: | CE8: 45547 | CG8: As per Gross of BOC | CH8: =CH6+CH7 -> 1701789.8 | CI8: =CH8/CC16 -> 78.896142 | CJ8: =CH8/CE17 -> 69.426384 | CL8: Date: | CM8: 45433 | CO8: Date Received: | CP8: 45314 | CR8: As per Gross of BOC | CS8: =CS6+CS7 -> 1706640.7 | CT8: =CS8/CN16 -> 79.378636 | CU8: =CS8/CP17 -> 69.850964 | CW8: Date: | CX8: 45515 | CZ8: Date Received: | DA8: 45547 | DC8: As per Gross of BOC | DD8: =DD6+DD7 -> 1899155.3 | DE8: =DD8/CY16 -> 88.046142 | DF8: =DD8/DA17 -> 77.478126 | DI8: Date: | DJ8: 45515 | DL8: Date Received: | DM8: 45547 | DO8: As per Gross of BOC | DP8: =DP6+DP7 -> 2150231.3 | DQ8: =DP8/DK16 -> 99.686198 | DR8: =DP8/DM17 -> 87.721047
B9: Type of Oil: | C9: RBD PALM OLEIN | H9: As per Net of BOC | I9: =I8-J21 -> 1949168.1 | J9: =I9/D16 -> 94.208221 | K9: =I9/F17 -> 82.900582 | M9: Type of Oil: | N9: RBD PALM OLEIN | S9: As per Net of BOC | T9: =T8-U21 -> 1387954.8 | U9: =T9/O16 -> 64.979157 | V9: =T9/Q17 -> 57.179828 | X9: Type of Oil: | Y9: RBD PALM OLEIN | AD9: As per Net of BOC | AE9: =AE8-AF21 -> 1558761.5 | AF9: =AE9/Z16 -> 73.665477 | AG9: =AE9/AB17 -> 64.823545 | AI9: Type of Oil: | AJ9: RBD PALM OLEIN | AO9: As per Net of BOC | AP9: =AP8-AQ21 -> 1537491.8 | AQ9: =AP9/AK16 -> 72.523197 | AR9: =AP9/AM17 -> 63.818371 | AT9: Type of Oil: | AU9: RBD PALM OLEIN | AZ9: As per Net of BOC | BA9: =BA8-BB21 -> 1444938.5 | BB9: =BA9/AV16 -> 68.061165 | BC9: =BA9/AX17 -> 59.891909 | BE9: Type of Oil: | BF9: RBD PALM OLEIN | BK9: As per Net of BOC | BL9: =BL8-BM21 -> 1452477.4 | BM9: =BL9/BG16 -> 67.557091 | BN9: =BL9/BI17 -> 59.448337 | BP9: Type of Oil: | BQ9: RBD PALM OLEIN | BV9: As per Net of BOC | BW9: =BW8-BX21 -> 1473192.8 | BX9: =BW9/BR16 -> 68.520597 | BY9: =BW9/BT17 -> 60.296196 | CA9: Type of Oil: | CB9: RBD PALM OLEIN | CG9: As per Net of BOC | CH9: =CH8-CI21 -> 1512809.6 | CI9: =CH9/CC16 -> 70.13489 | CJ9: =CH9/CE17 -> 61.716728 | CL9: Type of Oil: | CM9: RBD PALM OLEIN | CR9: As per Net of BOC | CS9: =CS8-CT21 -> 1512537.8 | CT9: =CS9/CN16 -> 70.350597 | CU9: =CS9/CP17 -> 61.906545 | CW9: Type of Oil: | CX9: RBD PALM OLEIN | DC9: As per Net of BOC | DD9: =DD8-DE21 -> 1710175.1 | DE9: =DD9/CY16 -> 79.28489 | DF9: =DD9/DA17 -> 69.768471 | DI9: Type of Oil: | DJ9: RBD PALM OLEIN | DO9: As per Net of BOC | DP9: =DP8-DQ21 -> 1961251.1 | DQ9: =DP9/DK16 -> 90.924946 | DR9: =DP9/DM17 -> 80.011392
H10: For COGS | I10: =F22+J21+F38 -> 1990607.5 | J10: =I10/D16 -> 96.211092 | K10: =I10/F17 -> 84.663052 | S10: For COGS | T10: =Q22+U21+Q38 -> 1458989.3 | U10: =T10/O16 -> 68.304742 | V10: =T10/Q17 -> 60.106249 | AD10: For COGS | AE10: =AB22+AF21+AB38 -> 1621987.5 | AF10: =AE10/Z16 -> 76.653474 | AG10: =AE10/AB17 -> 67.452899 | AO10: For COGS | AP10: =AM22+AQ21+AM38 -> 1598180.9 | AQ10: =AP10/AK16 -> 75.385891 | AR10: =AP10/AM17 -> 66.337461 | AZ10: For COGS | BA10: =AX22+BB21+AX38 -> 1504082.4 | BB10: =BA10/AV16 -> 70.847028 | BC10: =BA10/AX17 -> 62.343389 | BF10: MSE240659 | BK10: For COGS | BL10: =BI22+BM21+BI38 -> 1532920.7 | BM10: =BL10/BG16 -> 71.298639 | BN10: =BL10/BI17 -> 62.740795 | BQ10: MSE240731 | BV10: For COGS | BW10: =BT22+BX21+BT38 -> 1544947.8 | BX10: =BW10/BR16 -> 71.858039 | BY10: =BW10/BT17 -> 63.233051 | CB10: MSE240978 | CG10: For COGS | CH10: =CE22+CI21+CE38 -> 1570538.7 | CI10: =CH10/CC16 -> 72.811252 | CJ10: =CH10/CE17 -> 64.071852 | CM10: MSE240731 | CR10: For COGS | CS10: =CP22+CT21+CP38 -> 1584292.8 | CT10: =CS10/CN16 -> 73.688039 | CU10: =CS10/CP17 -> 64.843399 | CX10: MSE240978 | DC10: For COGS | DD10: =DA22+DE21+DA38 -> 1767904.2 | DE10: =DD10/CY16 -> 81.961252 | DF10: =DD10/DA17 -> 72.123594 | DJ10: MSE240978 | DO10: For COGS | DP10: =DM22+DQ21+DM38 -> 2018980.2 | DQ10: =DP10/DK16 -> 93.601308 | DR10: =DP10/DM17 -> 82.366515
B12: DETAILS OF PAYMENT | M12: DETAILS OF PAYMENT | X12: DETAILS OF PAYMENT | AI12: DETAILS OF PAYMENT | AT12: DETAILS OF PAYMENT | BE12: DETAILS OF PAYMENT | BP12: DETAILS OF PAYMENT | CA12: DETAILS OF PAYMENT | CL12: DETAILS OF PAYMENT | CW12: DETAILS OF PAYMENT | DI12: DETAILS OF PAYMENT
B15: ORDER DETAILS (FOREIGN) | H15: COMPUTATION OF TAXES AND DUTIES | M15: ORDER DETAILS (FOREIGN) | S15: COMPUTATION OF TAXES AND DUTIES | X15: ORDER DETAILS (FOREIGN) | AD15: COMPUTATION OF TAXES AND DUTIES | AI15: ORDER DETAILS (FOREIGN) | AO15: COMPUTATION OF TAXES AND DUTIES | AT15: ORDER DETAILS (FOREIGN) | AZ15: COMPUTATION OF TAXES AND DUTIES | BE15: ORDER DETAILS (FOREIGN) | BK15: COMPUTATION OF TAXES AND DUTIES | BP15: ORDER DETAILS (FOREIGN) | BV15: COMPUTATION OF TAXES AND DUTIES | CA15: ORDER DETAILS (FOREIGN) | CG15: COMPUTATION OF TAXES AND DUTIES | CL15: ORDER DETAILS (FOREIGN) | CR15: COMPUTATION OF TAXES AND DUTIES | CW15: ORDER DETAILS (FOREIGN) | DC15: COMPUTATION OF TAXES AND DUTIES | DI15: ORDER DETAILS (FOREIGN) | DO15: COMPUTATION OF TAXES AND DUTIES
B16: ITEM NET WEIGHT (KG) | D16: 20690 | E16: PRICE PER KG | F16: 1.428 | H16: VAT PH (12%) | J16: Formulated | K16: =F35*0.12 -> 229176.49 | M16: ITEM NET WEIGHT (KG) | O16: 21360 | P16: PRICE PER KG | Q16: =20826/O16 -> 0.975 | S16: VAT PH (12%) | U16: Formulated | V16: =Q35*0.12 -> 163938.59 | X16: ITEM NET WEIGHT (KG) | Z16: 21160 | AA16: PRICE PER KG | AB16: 1.12 | AD16: VAT PH (12%) | AF16: Formulated | AG16: =AB35*0.12 -> 185728.58 | AI16: ITEM NET WEIGHT (KG) | AK16: 21200 | AL16: PRICE PER KG | AM16: 1.093 | AO16: VAT PH (12%) | AQ16: Formulated | AR16: =AM35*0.12 -> 181624.65 | AT16: ITEM NET WEIGHT (KG) | AV16: 21230 | AW16: PRICE PER KG | AX16: 1.02 | AZ16: VAT PH (12%) | BB16: Formulated | BC16: =AX35*0.12 -> 169057.27 | BE16: ITEM NET WEIGHT (KG) | BG16: =21930/1.02 -> 21500 | BH16: PRICE PER KG | BI16: 1.02 | BK16: VAT PH (12%) | BM16: Formulated | BN16: =BI35*0.12 -> 171477.16 | BP16: ITEM NET WEIGHT (KG) | BR16: 21500 | BS16: PRICE PER KG | BT16: 1.03 | BV16: VAT PH (12%) | BX16: Formulated | BY16: =BT35*0.12 -> 172653.36 | CA16: ITEM NET WEIGHT (KG) | CC16: 21570 | CD16: PRICE PER KG | CE16: 1.05 | CG16: VAT PH (12%) | CI16: Formulated | CJ16: =CE35*0.12 -> 176332.6 | CL16: ITEM NET WEIGHT (KG) | CN16: 21500 | CO16: PRICE PER KG | CP16: 1.06 | CR16: VAT PH (12%) | CT16: Formulated | CU16: =CP35*0.12 -> 177374.76 | CW16: ITEM NET WEIGHT (KG) | CY16: 21570 | CZ16: PRICE PER KG | DA16: 1.2 | DC16: VAT PH (12%) | DE16: Formulated | DF16: =DA35*0.12 -> 200016.46 | DI16: ITEM NET WEIGHT (KG) | DK16: 21570 | DL16: PRICE PER KG | DM16: 1.2 | DO16: VAT PH (12%) | DQ16: Formulated | DR16: =DM35*0.12 -> 230145.58
